2025-05-21 00:16:50,359 - error_logger - ERROR - Error in global_exception: error_handler() got an unexpected keyword argument 'location'
2025-05-21 00:18:35,965 - error_logger - ERROR - Error in global_exception: error_handler() got an unexpected keyword argument 'location'
2025-05-21 00:20:23,608 - error_logger - ERROR - Error in global_exception: 'str' object has no attribute 'update_id'
2025-05-21 00:21:43,200 - error_logger - ERROR - Error in global_exception: 'str' object has no attribute '__qualname__'
2025-05-20 19:00:44,310 - error_logger - ERROR - Error in telegram_update: Conflict: terminated by other getUpdates request; make sure that only one bot instance is running
2025-05-20 19:00:50,112 - error_logger - ERROR - Error in telegram_update: Conflict: terminated by other getUpdates request; make sure that only one bot instance is running
2025-05-20 19:00:57,157 - error_logger - ERROR - Error in telegram_update: Conflict: terminated by other getUpdates request; make sure that only one bot instance is running
2025-05-20 19:01:03,093 - error_logger - ERROR - Error in telegram_update: Conflict: terminated by other getUpdates request; make sure that only one bot instance is running
2025-05-20 20:58:07,058 - error_logger - ERROR - Error in telegram_update: urllib3 HTTPError HTTPSConnectionPool(host='api.telegram.org', port=443): Max retries exceeded with url: /bot7593677131:AAEpUpS8NkD6gIOU5o26xvtbjOq15g_rLis/getUpdates (Caused by ProxyError('Cannot connect to proxy.', NewConnectionError('<telegram.vendor.ptb_urllib3.urllib3.connection.VerifiedHTTPSConnection object at 0x7453e67eb490>: Failed to establish a new connection: [Errno 111] Connection refused')))
2025-05-20 21:46:06,705 - error_logger - ERROR - Error in telegram_update: urllib3 HTTPError HTTPSConnectionPool(host='api.telegram.org', port=443): Max retries exceeded with url: /bot7593677131:AAEpUpS8NkD6gIOU5o26xvtbjOq15g_rLis/getUpdates (Caused by ProxyError('Cannot connect to proxy.', NewConnectionError('<telegram.vendor.ptb_urllib3.urllib3.connection.VerifiedHTTPSConnection object at 0x7453e67e9210>: Failed to establish a new connection: [Errno 111] Connection refused')))
2025-05-20 22:26:06,884 - error_logger - ERROR - Error in telegram_update: urllib3 HTTPError HTTPSConnectionPool(host='api.telegram.org', port=443): Max retries exceeded with url: /bot7593677131:AAEpUpS8NkD6gIOU5o26xvtbjOq15g_rLis/getUpdates (Caused by ProxyError('Cannot connect to proxy.', NewConnectionError('<telegram.vendor.ptb_urllib3.urllib3.connection.VerifiedHTTPSConnection object at 0x7453e67d34d0>: Failed to establish a new connection: [Errno 111] Connection refused')))
2025-05-20 23:10:11,468 - error_logger - ERROR - Error in telegram_update: urllib3 HTTPError HTTPSConnectionPool(host='api.telegram.org', port=443): Max retries exceeded with url: /bot7593677131:AAEpUpS8NkD6gIOU5o26xvtbjOq15g_rLis/getUpdates (Caused by ProxyError('Cannot connect to proxy.', NewConnectionError('<telegram.vendor.ptb_urllib3.urllib3.connection.VerifiedHTTPSConnection object at 0x7453e67f1810>: Failed to establish a new connection: [Errno 111] Connection refused')))
2025-05-20 23:34:06,334 - error_logger - ERROR - Error in telegram_update: urllib3 HTTPError HTTPSConnectionPool(host='api.telegram.org', port=443): Max retries exceeded with url: /bot7593677131:AAEpUpS8NkD6gIOU5o26xvtbjOq15g_rLis/getUpdates (Caused by ProxyError('Cannot connect to proxy.', NewConnectionError('<telegram.vendor.ptb_urllib3.urllib3.connection.VerifiedHTTPSConnection object at 0x7453e67f1c50>: Failed to establish a new connection: [Errno 111] Connection refused')))
2025-05-21 12:08:50,734 - error_logger - ERROR - Error in telegram_update: urllib3 HTTPError HTTPSConnectionPool(host='api.telegram.org', port=443): Max retries exceeded with url: /bot7593677131:AAEpUpS8NkD6gIOU5o26xvtbjOq15g_rLis/getUpdates (Caused by ProxyError('Cannot connect to proxy.', OSError('Tunnel connection failed: 503 Service Unavailable')))
2025-05-21 12:08:51,736 - error_logger - ERROR - Error in telegram_update: urllib3 HTTPError HTTPSConnectionPool(host='api.telegram.org', port=443): Max retries exceeded with url: /bot7593677131:AAEpUpS8NkD6gIOU5o26xvtbjOq15g_rLis/getUpdates (Caused by ProxyError('Cannot connect to proxy.', OSError('Tunnel connection failed: 503 Service Unavailable')))
2025-05-21 12:08:53,245 - error_logger - ERROR - Error in telegram_update: urllib3 HTTPError HTTPSConnectionPool(host='api.telegram.org', port=443): Max retries exceeded with url: /bot7593677131:AAEpUpS8NkD6gIOU5o26xvtbjOq15g_rLis/getUpdates (Caused by ProxyError('Cannot connect to proxy.', OSError('Tunnel connection failed: 503 Service Unavailable')))
2025-05-21 12:08:55,499 - error_logger - ERROR - Error in telegram_update: urllib3 HTTPError HTTPSConnectionPool(host='api.telegram.org', port=443): Max retries exceeded with url: /bot7593677131:AAEpUpS8NkD6gIOU5o26xvtbjOq15g_rLis/getUpdates (Caused by ProxyError('Cannot connect to proxy.', OSError('Tunnel connection failed: 503 Service Unavailable')))
2025-05-21 12:08:58,880 - error_logger - ERROR - Error in telegram_update: urllib3 HTTPError HTTPSConnectionPool(host='api.telegram.org', port=443): Max retries exceeded with url: /bot7593677131:AAEpUpS8NkD6gIOU5o26xvtbjOq15g_rLis/getUpdates (Caused by ProxyError('Cannot connect to proxy.', OSError('Tunnel connection failed: 503 Service Unavailable')))
2025-05-21 12:09:03,948 - error_logger - ERROR - Error in telegram_update: urllib3 HTTPError HTTPSConnectionPool(host='api.telegram.org', port=443): Max retries exceeded with url: /bot7593677131:AAEpUpS8NkD6gIOU5o26xvtbjOq15g_rLis/getUpdates (Caused by ProxyError('Cannot connect to proxy.', OSError('Tunnel connection failed: 503 Service Unavailable')))
2025-05-21 12:09:11,547 - error_logger - ERROR - Error in telegram_update: urllib3 HTTPError HTTPSConnectionPool(host='api.telegram.org', port=443): Max retries exceeded with url: /bot7593677131:AAEpUpS8NkD6gIOU5o26xvtbjOq15g_rLis/getUpdates (Caused by ProxyError('Cannot connect to proxy.', OSError('Tunnel connection failed: 503 Service Unavailable')))
2025-05-21 12:09:22,941 - error_logger - ERROR - Error in telegram_update: urllib3 HTTPError HTTPSConnectionPool(host='api.telegram.org', port=443): Max retries exceeded with url: /bot7593677131:AAEpUpS8NkD6gIOU5o26xvtbjOq15g_rLis/getUpdates (Caused by ProxyError('Cannot connect to proxy.', OSError('Tunnel connection failed: 503 Service Unavailable')))
2025-05-21 12:09:40,031 - error_logger - ERROR - Error in telegram_update: urllib3 HTTPError HTTPSConnectionPool(host='api.telegram.org', port=443): Max retries exceeded with url: /bot7593677131:AAEpUpS8NkD6gIOU5o26xvtbjOq15g_rLis/getUpdates (Caused by ProxyError('Cannot connect to proxy.', OSError('Tunnel connection failed: 503 Service Unavailable')))
2025-05-21 12:10:05,672 - error_logger - ERROR - Error in telegram_update: urllib3 HTTPError HTTPSConnectionPool(host='api.telegram.org', port=443): Max retries exceeded with url: /bot7593677131:AAEpUpS8NkD6gIOU5o26xvtbjOq15g_rLis/getUpdates (Caused by ProxyError('Cannot connect to proxy.', OSError('Tunnel connection failed: 503 Service Unavailable')))
2025-05-21 12:10:44,119 - error_logger - ERROR - Error in telegram_update: urllib3 HTTPError HTTPSConnectionPool(host='api.telegram.org', port=443): Max retries exceeded with url: /bot7593677131:AAEpUpS8NkD6gIOU5o26xvtbjOq15g_rLis/getUpdates (Caused by ProxyError('Cannot connect to proxy.', OSError('Tunnel connection failed: 503 Service Unavailable')))
2025-05-21 12:11:14,126 - error_logger - ERROR - Error in telegram_update: urllib3 HTTPError HTTPSConnectionPool(host='api.telegram.org', port=443): Max retries exceeded with url: /bot7593677131:AAEpUpS8NkD6gIOU5o26xvtbjOq15g_rLis/getUpdates (Caused by ProxyError('Cannot connect to proxy.', OSError('Tunnel connection failed: 503 Service Unavailable')))
2025-05-21 12:11:44,131 - error_logger - ERROR - Error in telegram_update: urllib3 HTTPError HTTPSConnectionPool(host='api.telegram.org', port=443): Max retries exceeded with url: /bot7593677131:AAEpUpS8NkD6gIOU5o26xvtbjOq15g_rLis/getUpdates (Caused by ProxyError('Cannot connect to proxy.', OSError('Tunnel connection failed: 503 Service Unavailable')))
2025-05-22 21:08:10,543 - error_logger - ERROR - Error in forward: 'NoneType' object has no attribute 'text'
2025-05-22 21:08:10,568 - error_logger - ERROR - Error in telegram_update: 'NoneType' object has no attribute 'text'
2025-05-23 00:32:06,741 - error_logger - ERROR - Error in telegram_update: urllib3 HTTPError HTTPSConnectionPool(host='api.telegram.org', port=443): Max retries exceeded with url: /bot7593677131:AAEpUpS8NkD6gIOU5o26xvtbjOq15g_rLis/getUpdates (Caused by ProxyError('Cannot connect to proxy.', NewConnectionError('<telegram.vendor.ptb_urllib3.urllib3.connection.VerifiedHTTPSConnection object at 0x7291645096d0>: Failed to establish a new connection: [Errno 111] Connection refused')))
2025-05-23 01:52:06,887 - error_logger - ERROR - Error in telegram_update: urllib3 HTTPError HTTPSConnectionPool(host='api.telegram.org', port=443): Max retries exceeded with url: /bot7593677131:AAEpUpS8NkD6gIOU5o26xvtbjOq15g_rLis/getUpdates (Caused by ProxyError('Cannot connect to proxy.', NewConnectionError('<telegram.vendor.ptb_urllib3.urllib3.connection.VerifiedHTTPSConnection object at 0x7291644f89d0>: Failed to establish a new connection: [Errno 111] Connection refused')))
2025-05-23 02:20:09,995 - error_logger - ERROR - Error in telegram_update: urllib3 HTTPError HTTPSConnectionPool(host='api.telegram.org', port=443): Max retries exceeded with url: /bot7593677131:AAEpUpS8NkD6gIOU5o26xvtbjOq15g_rLis/getUpdates (Caused by ProxyError('Cannot connect to proxy.', NewConnectionError('<telegram.vendor.ptb_urllib3.urllib3.connection.VerifiedHTTPSConnection object at 0x7291644f9090>: Failed to establish a new connection: [Errno 111] Connection refused')))
2025-05-23 03:02:07,437 - error_logger - ERROR - Error in telegram_update: urllib3 HTTPError HTTPSConnectionPool(host='api.telegram.org', port=443): Max retries exceeded with url: /bot7593677131:AAEpUpS8NkD6gIOU5o26xvtbjOq15g_rLis/getUpdates (Caused by ProxyError('Cannot connect to proxy.', NewConnectionError('<telegram.vendor.ptb_urllib3.urllib3.connection.VerifiedHTTPSConnection object at 0x7291656bad10>: Failed to establish a new connection: [Errno 111] Connection refused')))
2025-05-23 04:02:06,921 - error_logger - ERROR - Error in telegram_update: urllib3 HTTPError HTTPSConnectionPool(host='api.telegram.org', port=443): Max retries exceeded with url: /bot7593677131:AAEpUpS8NkD6gIOU5o26xvtbjOq15g_rLis/getUpdates (Caused by ProxyError('Cannot connect to proxy.', NewConnectionError('<telegram.vendor.ptb_urllib3.urllib3.connection.VerifiedHTTPSConnection object at 0x729164504e90>: Failed to establish a new connection: [Errno 111] Connection refused')))
2025-05-23 04:40:11,060 - error_logger - ERROR - Error in telegram_update: urllib3 HTTPError HTTPSConnectionPool(host='api.telegram.org', port=443): Max retries exceeded with url: /bot7593677131:AAEpUpS8NkD6gIOU5o26xvtbjOq15g_rLis/getUpdates (Caused by ProxyError('Cannot connect to proxy.', NewConnectionError('<telegram.vendor.ptb_urllib3.urllib3.connection.VerifiedHTTPSConnection object at 0x729164505d50>: Failed to establish a new connection: [Errno 111] Connection refused')))
2025-05-23 05:10:09,384 - error_logger - ERROR - Error in telegram_update: urllib3 HTTPError HTTPSConnectionPool(host='api.telegram.org', port=443): Max retries exceeded with url: /bot7593677131:AAEpUpS8NkD6gIOU5o26xvtbjOq15g_rLis/getUpdates (Caused by ProxyError('Cannot connect to proxy.', NewConnectionError('<telegram.vendor.ptb_urllib3.urllib3.connection.VerifiedHTTPSConnection object at 0x72916452c7d0>: Failed to establish a new connection: [Errno 111] Connection refused')))
2025-05-23 06:20:09,487 - error_logger - ERROR - Error in telegram_update: urllib3 HTTPError HTTPSConnectionPool(host='api.telegram.org', port=443): Max retries exceeded with url: /bot7593677131:AAEpUpS8NkD6gIOU5o26xvtbjOq15g_rLis/getUpdates (Caused by ProxyError('Cannot connect to proxy.', NewConnectionError('<telegram.vendor.ptb_urllib3.urllib3.connection.VerifiedHTTPSConnection object at 0x72916452ea50>: Failed to establish a new connection: [Errno 111] Connection refused')))
2025-05-23 09:08:06,933 - error_logger - ERROR - Error in telegram_update: urllib3 HTTPError HTTPSConnectionPool(host='api.telegram.org', port=443): Max retries exceeded with url: /bot7593677131:AAEpUpS8NkD6gIOU5o26xvtbjOq15g_rLis/getUpdates (Caused by ProxyError('Cannot connect to proxy.', NewConnectionError('<telegram.vendor.ptb_urllib3.urllib3.connection.VerifiedHTTPSConnection object at 0x729164504850>: Failed to establish a new connection: [Errno 111] Connection refused')))
2025-05-23 13:06:06,348 - error_logger - ERROR - Error in telegram_update: urllib3 HTTPError HTTPSConnectionPool(host='api.telegram.org', port=443): Max retries exceeded with url: /bot7593677131:AAEpUpS8NkD6gIOU5o26xvtbjOq15g_rLis/getUpdates (Caused by ProxyError('Cannot connect to proxy.', NewConnectionError('<telegram.vendor.ptb_urllib3.urllib3.connection.VerifiedHTTPSConnection object at 0x729164507710>: Failed to establish a new connection: [Errno 111] Connection refused')))
2025-05-23 18:28:03,703 - error_logger - ERROR - Error in forward: 'NoneType' object has no attribute 'text'
2025-05-23 18:28:04,105 - error_logger - ERROR - Error in telegram_update: 'NoneType' object has no attribute 'text'
2025-05-24 01:48:06,887 - error_logger - ERROR - Error in telegram_update: urllib3 HTTPError HTTPSConnectionPool(host='api.telegram.org', port=443): Max retries exceeded with url: /bot7593677131:AAEpUpS8NkD6gIOU5o26xvtbjOq15g_rLis/getUpdates (Caused by ProxyError('Cannot connect to proxy.', NewConnectionError('<telegram.vendor.ptb_urllib3.urllib3.connection.VerifiedHTTPSConnection object at 0x7ed8944f7910>: Failed to establish a new connection: [Errno 111] Connection refused')))
2025-05-24 04:36:06,431 - error_logger - ERROR - Error in telegram_update: urllib3 HTTPError HTTPSConnectionPool(host='api.telegram.org', port=443): Max retries exceeded with url: /bot7593677131:AAEpUpS8NkD6gIOU5o26xvtbjOq15g_rLis/getUpdates (Caused by ProxyError('Cannot connect to proxy.', NewConnectionError('<telegram.vendor.ptb_urllib3.urllib3.connection.VerifiedHTTPSConnection object at 0x7ed8944f21d0>: Failed to establish a new connection: [Errno 111] Connection refused')))
2025-05-24 07:00:22,794 - error_logger - ERROR - Error in telegram_update: urllib3 HTTPError HTTPSConnectionPool(host='api.telegram.org', port=443): Max retries exceeded with url: /bot7593677131:AAEpUpS8NkD6gIOU5o26xvtbjOq15g_rLis/getUpdates (Caused by ProxyError('Cannot connect to proxy.', NewConnectionError('<telegram.vendor.ptb_urllib3.urllib3.connection.VerifiedHTTPSConnection object at 0x78ca1d404450>: Failed to establish a new connection: [Errno 111] Connection refused')))
2025-05-24 08:30:19,650 - error_logger - ERROR - Error in telegram_update: urllib3 HTTPError HTTPSConnectionPool(host='api.telegram.org', port=443): Max retries exceeded with url: /bot7593677131:AAEpUpS8NkD6gIOU5o26xvtbjOq15g_rLis/getUpdates (Caused by ProxyError('Cannot connect to proxy.', NewConnectionError('<telegram.vendor.ptb_urllib3.urllib3.connection.VerifiedHTTPSConnection object at 0x78ca1d3fd6d0>: Failed to establish a new connection: [Errno 111] Connection refused')))
2025-05-24 08:44:07,487 - error_logger - ERROR - Error in telegram_update: urllib3 HTTPError HTTPSConnectionPool(host='api.telegram.org', port=443): Max retries exceeded with url: /bot7593677131:AAEpUpS8NkD6gIOU5o26xvtbjOq15g_rLis/getUpdates (Caused by ProxyError('Cannot connect to proxy.', NewConnectionError('<telegram.vendor.ptb_urllib3.urllib3.connection.VerifiedHTTPSConnection object at 0x78ca1d3fc910>: Failed to establish a new connection: [Errno 111] Connection refused')))
2025-05-24 10:12:06,599 - error_logger - ERROR - Error in telegram_update: urllib3 HTTPError HTTPSConnectionPool(host='api.telegram.org', port=443): Max retries exceeded with url: /bot7593677131:AAEpUpS8NkD6gIOU5o26xvtbjOq15g_rLis/getUpdates (Caused by ProxyError('Cannot connect to proxy.', NewConnectionError('<telegram.vendor.ptb_urllib3.urllib3.connection.VerifiedHTTPSConnection object at 0x78ca1d3fe2d0>: Failed to establish a new connection: [Errno 111] Connection refused')))
2025-05-24 11:32:07,178 - error_logger - ERROR - Error in telegram_update: urllib3 HTTPError HTTPSConnectionPool(host='api.telegram.org', port=443): Max retries exceeded with url: /bot7593677131:AAEpUpS8NkD6gIOU5o26xvtbjOq15g_rLis/getUpdates (Caused by ProxyError('Cannot connect to proxy.', NewConnectionError('<telegram.vendor.ptb_urllib3.urllib3.connection.VerifiedHTTPSConnection object at 0x78ca1d3fd890>: Failed to establish a new connection: [Errno 111] Connection refused')))
2025-05-24 14:08:07,442 - error_logger - ERROR - Error in telegram_update: urllib3 HTTPError HTTPSConnectionPool(host='api.telegram.org', port=443): Max retries exceeded with url: /bot7593677131:AAEpUpS8NkD6gIOU5o26xvtbjOq15g_rLis/getUpdates (Caused by ProxyError('Cannot connect to proxy.', NewConnectionError('<telegram.vendor.ptb_urllib3.urllib3.connection.VerifiedHTTPSConnection object at 0x78ca1d3f8390>: Failed to establish a new connection: [Errno 111] Connection refused')))
2025-05-24 14:12:06,738 - error_logger - ERROR - Error in telegram_update: urllib3 HTTPError HTTPSConnectionPool(host='api.telegram.org', port=443): Max retries exceeded with url: /bot7593677131:AAEpUpS8NkD6gIOU5o26xvtbjOq15g_rLis/getUpdates (Caused by ProxyError('Cannot connect to proxy.', NewConnectionError('<telegram.vendor.ptb_urllib3.urllib3.connection.VerifiedHTTPSConnection object at 0x78ca1d3f9b90>: Failed to establish a new connection: [Errno 111] Connection refused')))
2025-05-24 17:20:11,914 - error_logger - ERROR - Error in telegram_update: urllib3 HTTPError HTTPSConnectionPool(host='api.telegram.org', port=443): Max retries exceeded with url: /bot7593677131:AAEpUpS8NkD6gIOU5o26xvtbjOq15g_rLis/getUpdates (Caused by ProxyError('Cannot connect to proxy.', NewConnectionError('<telegram.vendor.ptb_urllib3.urllib3.connection.VerifiedHTTPSConnection object at 0x78ca1d3f8950>: Failed to establish a new connection: [Errno 111] Connection refused')))
2025-05-24 18:18:06,745 - error_logger - ERROR - Error in telegram_update: urllib3 HTTPError HTTPSConnectionPool(host='api.telegram.org', port=443): Max retries exceeded with url: /bot7593677131:AAEpUpS8NkD6gIOU5o26xvtbjOq15g_rLis/getUpdates (Caused by ProxyError('Cannot connect to proxy.', NewConnectionError('<telegram.vendor.ptb_urllib3.urllib3.connection.VerifiedHTTPSConnection object at 0x7595f6198cd0>: Failed to establish a new connection: [Errno 111] Connection refused')))
2025-05-25 18:07:23,053 - error_logger - ERROR - Error in start: Forbidden: bot was blocked by the user
2025-05-25 18:07:23,073 - error_logger - ERROR - Error in telegram_update: Forbidden: bot was blocked by the user
2025-05-25 18:07:23,591 - error_logger - ERROR - Error in telegram_update: Forbidden: bot was blocked by the user
2025-05-25 18:12:06,761 - error_logger - ERROR - Error in telegram_update: urllib3 HTTPError HTTPSConnectionPool(host='api.telegram.org', port=443): Max retries exceeded with url: /bot7593677131:AAEpUpS8NkD6gIOU5o26xvtbjOq15g_rLis/getUpdates (Caused by ProxyError('Cannot connect to proxy.', NewConnectionError('<telegram.vendor.ptb_urllib3.urllib3.connection.VerifiedHTTPSConnection object at 0x709c13453d90>: Failed to establish a new connection: [Errno 111] Connection refused')))
2025-05-25 18:15:57,258 - error_logger - ERROR - Error in telegram_update: Conflict: terminated by other getUpdates request; make sure that only one bot instance is running
2025-05-25 18:15:58,345 - error_logger - ERROR - Error in telegram_update: Conflict: terminated by other getUpdates request; make sure that only one bot instance is running
2025-05-25 18:16:04,530 - error_logger - ERROR - Error in telegram_update: Conflict: terminated by other getUpdates request; make sure that only one bot instance is running
2025-05-25 18:16:12,225 - error_logger - ERROR - Error in telegram_update: Conflict: terminated by other getUpdates request; make sure that only one bot instance is running
2025-05-25 18:18:11,026 - error_logger - ERROR - Error in telegram_update: Conflict: terminated by other getUpdates request; make sure that only one bot instance is running
2025-05-25 18:18:15,115 - error_logger - ERROR - Error in telegram_update: Conflict: terminated by other getUpdates request; make sure that only one bot instance is running
2025-05-25 18:18:16,206 - error_logger - ERROR - Error in telegram_update: Conflict: terminated by other getUpdates request; make sure that only one bot instance is running
2025-05-25 18:18:20,795 - error_logger - ERROR - Error in telegram_update: Conflict: terminated by other getUpdates request; make sure that only one bot instance is running
2025-05-25 18:18:22,387 - error_logger - ERROR - Error in telegram_update: Conflict: terminated by other getUpdates request; make sure that only one bot instance is running
2025-05-25 18:18:27,726 - error_logger - ERROR - Error in telegram_update: Conflict: terminated by other getUpdates request; make sure that only one bot instance is running
2025-05-25 18:18:30,069 - error_logger - ERROR - Error in telegram_update: Conflict: terminated by other getUpdates request; make sure that only one bot instance is running
2025-05-25 18:18:33,534 - error_logger - ERROR - Error in telegram_update: Conflict: terminated by other getUpdates request; make sure that only one bot instance is running
2025-05-25 18:18:37,001 - error_logger - ERROR - Error in telegram_update: Conflict: terminated by other getUpdates request; make sure that only one bot instance is running
2025-05-25 18:18:42,152 - error_logger - ERROR - Error in telegram_update: Conflict: terminated by other getUpdates request; make sure that only one bot instance is running
2025-05-25 18:18:46,244 - error_logger - ERROR - Error in telegram_update: Conflict: terminated by other getUpdates request; make sure that only one bot instance is running
2025-05-25 18:18:53,927 - error_logger - ERROR - Error in telegram_update: Conflict: terminated by other getUpdates request; make sure that only one bot instance is running
2025-05-25 18:18:58,019 - error_logger - ERROR - Error in telegram_update: Conflict: terminated by other getUpdates request; make sure that only one bot instance is running
2025-05-25 18:19:09,500 - error_logger - ERROR - Error in telegram_update: Conflict: terminated by other getUpdates request; make sure that only one bot instance is running
2025-05-25 18:19:13,591 - error_logger - ERROR - Error in telegram_update: Conflict: terminated by other getUpdates request; make sure that only one bot instance is running
2025-05-25 18:19:30,936 - error_logger - ERROR - Error in telegram_update: Conflict: terminated by other getUpdates request; make sure that only one bot instance is running
2025-05-25 18:19:34,857 - error_logger - ERROR - Error in telegram_update: Conflict: terminated by other getUpdates request; make sure that only one bot instance is running
2025-05-25 18:20:00,572 - error_logger - ERROR - Error in telegram_update: Conflict: terminated by other getUpdates request; make sure that only one bot instance is running
2025-05-25 18:20:04,662 - error_logger - ERROR - Error in telegram_update: Conflict: terminated by other getUpdates request; make sure that only one bot instance is running
2025-05-25 19:06:07,872 - error_logger - ERROR - Error in telegram_update: urllib3 HTTPError HTTPSConnectionPool(host='api.telegram.org', port=443): Max retries exceeded with url: /bot7593677131:AAEpUpS8NkD6gIOU5o26xvtbjOq15g_rLis/getUpdates (Caused by ProxyError('Cannot connect to proxy.', NewConnectionError('<telegram.vendor.ptb_urllib3.urllib3.connection.VerifiedHTTPSConnection object at 0x7310630ee210>: Failed to establish a new connection: [Errno 111] Connection refused')))
2025-05-25 19:30:21,980 - error_logger - ERROR - Error in telegram_update: urllib3 HTTPError HTTPSConnectionPool(host='api.telegram.org', port=443): Max retries exceeded with url: /bot7593677131:AAEpUpS8NkD6gIOU5o26xvtbjOq15g_rLis/getUpdates (Caused by ProxyError('Cannot connect to proxy.', NewConnectionError('<telegram.vendor.ptb_urllib3.urllib3.connection.VerifiedHTTPSConnection object at 0x7310630ec690>: Failed to establish a new connection: [Errno 111] Connection refused')))
2025-05-25 19:48:06,422 - error_logger - ERROR - Error in telegram_update: urllib3 HTTPError HTTPSConnectionPool(host='api.telegram.org', port=443): Max retries exceeded with url: /bot7593677131:AAEpUpS8NkD6gIOU5o26xvtbjOq15g_rLis/getUpdates (Caused by ProxyError('Cannot connect to proxy.', NewConnectionError('<telegram.vendor.ptb_urllib3.urllib3.connection.VerifiedHTTPSConnection object at 0x7310630f4090>: Failed to establish a new connection: [Errno 111] Connection refused')))
2025-05-25 20:56:06,768 - error_logger - ERROR - Error in telegram_update: urllib3 HTTPError HTTPSConnectionPool(host='api.telegram.org', port=443): Max retries exceeded with url: /bot7593677131:AAEpUpS8NkD6gIOU5o26xvtbjOq15g_rLis/getUpdates (Caused by ProxyError('Cannot connect to proxy.', NewConnectionError('<telegram.vendor.ptb_urllib3.urllib3.connection.VerifiedHTTPSConnection object at 0x7310630ee990>: Failed to establish a new connection: [Errno 111] Connection refused')))
2025-05-25 21:18:08,475 - error_logger - ERROR - Error in telegram_update: urllib3 HTTPError HTTPSConnectionPool(host='api.telegram.org', port=443): Max retries exceeded with url: /bot7593677131:AAEpUpS8NkD6gIOU5o26xvtbjOq15g_rLis/getUpdates (Caused by ProxyError('Cannot connect to proxy.', NewConnectionError('<telegram.vendor.ptb_urllib3.urllib3.connection.VerifiedHTTPSConnection object at 0x7310630f6950>: Failed to establish a new connection: [Errno 111] Connection refused')))
2025-05-26 18:14:06,784 - error_logger - ERROR - Error in telegram_update: urllib3 HTTPError HTTPSConnectionPool(host='api.telegram.org', port=443): Max retries exceeded with url: /bot7593677131:AAEpUpS8NkD6gIOU5o26xvtbjOq15g_rLis/getUpdates (Caused by ProxyError('Cannot connect to proxy.', NewConnectionError('<telegram.vendor.ptb_urllib3.urllib3.connection.VerifiedHTTPSConnection object at 0x7d01db113c10>: Failed to establish a new connection: [Errno 111] Connection refused')))
2025-05-26 19:20:10,782 - error_logger - ERROR - Error in telegram_update: urllib3 HTTPError HTTPSConnectionPool(host='api.telegram.org', port=443): Max retries exceeded with url: /bot7593677131:AAEpUpS8NkD6gIOU5o26xvtbjOq15g_rLis/getUpdates (Caused by ProxyError('Cannot connect to proxy.', NewConnectionError('<telegram.vendor.ptb_urllib3.urllib3.connection.VerifiedHTTPSConnection object at 0x7d01db112990>: Failed to establish a new connection: [Errno 111] Connection refused')))
2025-05-26 19:48:06,990 - error_logger - ERROR - Error in telegram_update: urllib3 HTTPError HTTPSConnectionPool(host='api.telegram.org', port=443): Max retries exceeded with url: /bot7593677131:AAEpUpS8NkD6gIOU5o26xvtbjOq15g_rLis/getUpdates (Caused by ProxyError('Cannot connect to proxy.', NewConnectionError('<telegram.vendor.ptb_urllib3.urllib3.connection.VerifiedHTTPSConnection object at 0x7d01db0fcd50>: Failed to establish a new connection: [Errno 111] Connection refused')))
2025-06-03 17:03:23,784 - error_logger - ERROR - Error in start: Forbidden: bot was blocked by the user
2025-06-03 17:03:23,809 - error_logger - ERROR - Error in telegram_update: Forbidden: bot was blocked by the user
2025-06-03 17:03:24,428 - error_logger - ERROR - Error in start: Forbidden: bot was blocked by the user
2025-06-03 17:03:24,447 - error_logger - ERROR - Error in telegram_update: Forbidden: bot was blocked by the user
2025-06-03 17:03:24,997 - error_logger - ERROR - Error in start: Forbidden: bot was blocked by the user
2025-06-03 17:03:25,017 - error_logger - ERROR - Error in telegram_update: Forbidden: bot was blocked by the user
2025-06-03 17:03:25,587 - error_logger - ERROR - Error in start: Forbidden: bot was blocked by the user
2025-06-03 17:03:25,611 - error_logger - ERROR - Error in telegram_update: Forbidden: bot was blocked by the user
2025-06-03 19:50:54,392 - error_logger - ERROR - Error in forward: 'NoneType' object has no attribute 'text'
2025-06-03 19:50:54,423 - error_logger - ERROR - Error in telegram_update: 'NoneType' object has no attribute 'text'
2025-06-03 19:51:42,333 - error_logger - ERROR - Error in forward: 'NoneType' object has no attribute 'text'
2025-06-03 19:51:42,349 - error_logger - ERROR - Error in telegram_update: 'NoneType' object has no attribute 'text'
2025-06-04 00:18:05,554 - error_logger - ERROR - Error in telegram_update: urllib3 HTTPError HTTPSConnectionPool(host='api.telegram.org', port=443): Max retries exceeded with url: /bot7593677131:AAEpUpS8NkD6gIOU5o26xvtbjOq15g_rLis/getUpdates (Caused by ProxyError('Cannot connect to proxy.', NewConnectionError('<telegram.vendor.ptb_urllib3.urllib3.connection.VerifiedHTTPSConnection object at 0x7e0c105b5510>: Failed to establish a new connection: [Errno 111] Connection refused')))
2025-06-04 03:42:05,954 - error_logger - ERROR - Error in telegram_update: urllib3 HTTPError HTTPSConnectionPool(host='api.telegram.org', port=443): Max retries exceeded with url: /bot7593677131:AAEpUpS8NkD6gIOU5o26xvtbjOq15g_rLis/getUpdates (Caused by ProxyError('Cannot connect to proxy.', NewConnectionError('<telegram.vendor.ptb_urllib3.urllib3.connection.VerifiedHTTPSConnection object at 0x7e0c105b1a90>: Failed to establish a new connection: [Errno 111] Connection refused')))
2025-06-04 04:42:06,127 - error_logger - ERROR - Error in telegram_update: urllib3 HTTPError HTTPSConnectionPool(host='api.telegram.org', port=443): Max retries exceeded with url: /bot7593677131:AAEpUpS8NkD6gIOU5o26xvtbjOq15g_rLis/getUpdates (Caused by ProxyError('Cannot connect to proxy.', NewConnectionError('<telegram.vendor.ptb_urllib3.urllib3.connection.VerifiedHTTPSConnection object at 0x7e0c105b2e90>: Failed to establish a new connection: [Errno 111] Connection refused')))
2025-06-04 06:00:17,411 - error_logger - ERROR - Error in telegram_update: urllib3 HTTPError HTTPSConnectionPool(host='api.telegram.org', port=443): Max retries exceeded with url: /bot7593677131:AAEpUpS8NkD6gIOU5o26xvtbjOq15g_rLis/getUpdates (Caused by ProxyError('Cannot connect to proxy.', NewConnectionError('<telegram.vendor.ptb_urllib3.urllib3.connection.VerifiedHTTPSConnection object at 0x7e0c105c1910>: Failed to establish a new connection: [Errno 111] Connection refused')))
