2025-05-21 00:16:50,359 - error_logger - ERROR - Error in global_exception: error_handler() got an unexpected keyword argument 'location'
2025-05-21 00:18:35,965 - error_logger - ERROR - Error in global_exception: error_handler() got an unexpected keyword argument 'location'
2025-05-21 00:20:23,608 - error_logger - ERROR - Error in global_exception: 'str' object has no attribute 'update_id'
2025-05-21 00:21:43,200 - error_logger - ERROR - Error in global_exception: 'str' object has no attribute '__qualname__'
2025-05-20 19:00:44,310 - error_logger - ERROR - Error in telegram_update: Conflict: terminated by other getUpdates request; make sure that only one bot instance is running
2025-05-20 19:00:50,112 - error_logger - ERROR - Error in telegram_update: Conflict: terminated by other getUpdates request; make sure that only one bot instance is running
2025-05-20 19:00:57,157 - error_logger - ERROR - Error in telegram_update: Conflict: terminated by other getUpdates request; make sure that only one bot instance is running
2025-05-20 19:01:03,093 - error_logger - ERROR - Error in telegram_update: Conflict: terminated by other getUpdates request; make sure that only one bot instance is running
2025-05-20 20:58:07,058 - error_logger - ERROR - Error in telegram_update: urllib3 HTTPError HTTPSConnectionPool(host='api.telegram.org', port=443): Max retries exceeded with url: /bot7593677131:AAEpUpS8NkD6gIOU5o26xvtbjOq15g_rLis/getUpdates (Caused by ProxyError('Cannot connect to proxy.', NewConnectionError('<telegram.vendor.ptb_urllib3.urllib3.connection.VerifiedHTTPSConnection object at 0x7453e67eb490>: Failed to establish a new connection: [Errno 111] Connection refused')))
2025-05-20 21:46:06,705 - error_logger - ERROR - Error in telegram_update: urllib3 HTTPError HTTPSConnectionPool(host='api.telegram.org', port=443): Max retries exceeded with url: /bot7593677131:AAEpUpS8NkD6gIOU5o26xvtbjOq15g_rLis/getUpdates (Caused by ProxyError('Cannot connect to proxy.', NewConnectionError('<telegram.vendor.ptb_urllib3.urllib3.connection.VerifiedHTTPSConnection object at 0x7453e67e9210>: Failed to establish a new connection: [Errno 111] Connection refused')))
2025-05-20 22:26:06,884 - error_logger - ERROR - Error in telegram_update: urllib3 HTTPError HTTPSConnectionPool(host='api.telegram.org', port=443): Max retries exceeded with url: /bot7593677131:AAEpUpS8NkD6gIOU5o26xvtbjOq15g_rLis/getUpdates (Caused by ProxyError('Cannot connect to proxy.', NewConnectionError('<telegram.vendor.ptb_urllib3.urllib3.connection.VerifiedHTTPSConnection object at 0x7453e67d34d0>: Failed to establish a new connection: [Errno 111] Connection refused')))
2025-05-20 23:10:11,468 - error_logger - ERROR - Error in telegram_update: urllib3 HTTPError HTTPSConnectionPool(host='api.telegram.org', port=443): Max retries exceeded with url: /bot7593677131:AAEpUpS8NkD6gIOU5o26xvtbjOq15g_rLis/getUpdates (Caused by ProxyError('Cannot connect to proxy.', NewConnectionError('<telegram.vendor.ptb_urllib3.urllib3.connection.VerifiedHTTPSConnection object at 0x7453e67f1810>: Failed to establish a new connection: [Errno 111] Connection refused')))
2025-05-20 23:34:06,334 - error_logger - ERROR - Error in telegram_update: urllib3 HTTPError HTTPSConnectionPool(host='api.telegram.org', port=443): Max retries exceeded with url: /bot7593677131:AAEpUpS8NkD6gIOU5o26xvtbjOq15g_rLis/getUpdates (Caused by ProxyError('Cannot connect to proxy.', NewConnectionError('<telegram.vendor.ptb_urllib3.urllib3.connection.VerifiedHTTPSConnection object at 0x7453e67f1c50>: Failed to establish a new connection: [Errno 111] Connection refused')))
2025-05-21 12:08:50,734 - error_logger - ERROR - Error in telegram_update: urllib3 HTTPError HTTPSConnectionPool(host='api.telegram.org', port=443): Max retries exceeded with url: /bot7593677131:AAEpUpS8NkD6gIOU5o26xvtbjOq15g_rLis/getUpdates (Caused by ProxyError('Cannot connect to proxy.', OSError('Tunnel connection failed: 503 Service Unavailable')))
2025-05-21 12:08:51,736 - error_logger - ERROR - Error in telegram_update: urllib3 HTTPError HTTPSConnectionPool(host='api.telegram.org', port=443): Max retries exceeded with url: /bot7593677131:AAEpUpS8NkD6gIOU5o26xvtbjOq15g_rLis/getUpdates (Caused by ProxyError('Cannot connect to proxy.', OSError('Tunnel connection failed: 503 Service Unavailable')))
2025-05-21 12:08:53,245 - error_logger - ERROR - Error in telegram_update: urllib3 HTTPError HTTPSConnectionPool(host='api.telegram.org', port=443): Max retries exceeded with url: /bot7593677131:AAEpUpS8NkD6gIOU5o26xvtbjOq15g_rLis/getUpdates (Caused by ProxyError('Cannot connect to proxy.', OSError('Tunnel connection failed: 503 Service Unavailable')))
2025-05-21 12:08:55,499 - error_logger - ERROR - Error in telegram_update: urllib3 HTTPError HTTPSConnectionPool(host='api.telegram.org', port=443): Max retries exceeded with url: /bot7593677131:AAEpUpS8NkD6gIOU5o26xvtbjOq15g_rLis/getUpdates (Caused by ProxyError('Cannot connect to proxy.', OSError('Tunnel connection failed: 503 Service Unavailable')))
2025-05-21 12:08:58,880 - error_logger - ERROR - Error in telegram_update: urllib3 HTTPError HTTPSConnectionPool(host='api.telegram.org', port=443): Max retries exceeded with url: /bot7593677131:AAEpUpS8NkD6gIOU5o26xvtbjOq15g_rLis/getUpdates (Caused by ProxyError('Cannot connect to proxy.', OSError('Tunnel connection failed: 503 Service Unavailable')))
2025-05-21 12:09:03,948 - error_logger - ERROR - Error in telegram_update: urllib3 HTTPError HTTPSConnectionPool(host='api.telegram.org', port=443): Max retries exceeded with url: /bot7593677131:AAEpUpS8NkD6gIOU5o26xvtbjOq15g_rLis/getUpdates (Caused by ProxyError('Cannot connect to proxy.', OSError('Tunnel connection failed: 503 Service Unavailable')))
2025-05-21 12:09:11,547 - error_logger - ERROR - Error in telegram_update: urllib3 HTTPError HTTPSConnectionPool(host='api.telegram.org', port=443): Max retries exceeded with url: /bot7593677131:AAEpUpS8NkD6gIOU5o26xvtbjOq15g_rLis/getUpdates (Caused by ProxyError('Cannot connect to proxy.', OSError('Tunnel connection failed: 503 Service Unavailable')))
2025-05-21 12:09:22,941 - error_logger - ERROR - Error in telegram_update: urllib3 HTTPError HTTPSConnectionPool(host='api.telegram.org', port=443): Max retries exceeded with url: /bot7593677131:AAEpUpS8NkD6gIOU5o26xvtbjOq15g_rLis/getUpdates (Caused by ProxyError('Cannot connect to proxy.', OSError('Tunnel connection failed: 503 Service Unavailable')))
2025-05-21 12:09:40,031 - error_logger - ERROR - Error in telegram_update: urllib3 HTTPError HTTPSConnectionPool(host='api.telegram.org', port=443): Max retries exceeded with url: /bot7593677131:AAEpUpS8NkD6gIOU5o26xvtbjOq15g_rLis/getUpdates (Caused by ProxyError('Cannot connect to proxy.', OSError('Tunnel connection failed: 503 Service Unavailable')))
2025-05-21 12:10:05,672 - error_logger - ERROR - Error in telegram_update: urllib3 HTTPError HTTPSConnectionPool(host='api.telegram.org', port=443): Max retries exceeded with url: /bot7593677131:AAEpUpS8NkD6gIOU5o26xvtbjOq15g_rLis/getUpdates (Caused by ProxyError('Cannot connect to proxy.', OSError('Tunnel connection failed: 503 Service Unavailable')))
2025-05-21 12:10:44,119 - error_logger - ERROR - Error in telegram_update: urllib3 HTTPError HTTPSConnectionPool(host='api.telegram.org', port=443): Max retries exceeded with url: /bot7593677131:AAEpUpS8NkD6gIOU5o26xvtbjOq15g_rLis/getUpdates (Caused by ProxyError('Cannot connect to proxy.', OSError('Tunnel connection failed: 503 Service Unavailable')))
2025-05-21 12:11:14,126 - error_logger - ERROR - Error in telegram_update: urllib3 HTTPError HTTPSConnectionPool(host='api.telegram.org', port=443): Max retries exceeded with url: /bot7593677131:AAEpUpS8NkD6gIOU5o26xvtbjOq15g_rLis/getUpdates (Caused by ProxyError('Cannot connect to proxy.', OSError('Tunnel connection failed: 503 Service Unavailable')))
2025-05-21 12:11:44,131 - error_logger - ERROR - Error in telegram_update: urllib3 HTTPError HTTPSConnectionPool(host='api.telegram.org', port=443): Max retries exceeded with url: /bot7593677131:AAEpUpS8NkD6gIOU5o26xvtbjOq15g_rLis/getUpdates (Caused by ProxyError('Cannot connect to proxy.', OSError('Tunnel connection failed: 503 Service Unavailable')))
2025-05-22 21:08:10,543 - error_logger - ERROR - Error in forward: 'NoneType' object has no attribute 'text'
2025-05-22 21:08:10,568 - error_logger - ERROR - Error in telegram_update: 'NoneType' object has no attribute 'text'
2025-05-23 00:32:06,741 - error_logger - ERROR - Error in telegram_update: urllib3 HTTPError HTTPSConnectionPool(host='api.telegram.org', port=443): Max retries exceeded with url: /bot7593677131:AAEpUpS8NkD6gIOU5o26xvtbjOq15g_rLis/getUpdates (Caused by ProxyError('Cannot connect to proxy.', NewConnectionError('<telegram.vendor.ptb_urllib3.urllib3.connection.VerifiedHTTPSConnection object at 0x7291645096d0>: Failed to establish a new connection: [Errno 111] Connection refused')))
2025-05-23 01:52:06,887 - error_logger - ERROR - Error in telegram_update: urllib3 HTTPError HTTPSConnectionPool(host='api.telegram.org', port=443): Max retries exceeded with url: /bot7593677131:AAEpUpS8NkD6gIOU5o26xvtbjOq15g_rLis/getUpdates (Caused by ProxyError('Cannot connect to proxy.', NewConnectionError('<telegram.vendor.ptb_urllib3.urllib3.connection.VerifiedHTTPSConnection object at 0x7291644f89d0>: Failed to establish a new connection: [Errno 111] Connection refused')))
2025-05-23 02:20:09,995 - error_logger - ERROR - Error in telegram_update: urllib3 HTTPError HTTPSConnectionPool(host='api.telegram.org', port=443): Max retries exceeded with url: /bot7593677131:AAEpUpS8NkD6gIOU5o26xvtbjOq15g_rLis/getUpdates (Caused by ProxyError('Cannot connect to proxy.', NewConnectionError('<telegram.vendor.ptb_urllib3.urllib3.connection.VerifiedHTTPSConnection object at 0x7291644f9090>: Failed to establish a new connection: [Errno 111] Connection refused')))
2025-05-23 03:02:07,437 - error_logger - ERROR - Error in telegram_update: urllib3 HTTPError HTTPSConnectionPool(host='api.telegram.org', port=443): Max retries exceeded with url: /bot7593677131:AAEpUpS8NkD6gIOU5o26xvtbjOq15g_rLis/getUpdates (Caused by ProxyError('Cannot connect to proxy.', NewConnectionError('<telegram.vendor.ptb_urllib3.urllib3.connection.VerifiedHTTPSConnection object at 0x7291656bad10>: Failed to establish a new connection: [Errno 111] Connection refused')))
2025-05-23 04:02:06,921 - error_logger - ERROR - Error in telegram_update: urllib3 HTTPError HTTPSConnectionPool(host='api.telegram.org', port=443): Max retries exceeded with url: /bot7593677131:AAEpUpS8NkD6gIOU5o26xvtbjOq15g_rLis/getUpdates (Caused by ProxyError('Cannot connect to proxy.', NewConnectionError('<telegram.vendor.ptb_urllib3.urllib3.connection.VerifiedHTTPSConnection object at 0x729164504e90>: Failed to establish a new connection: [Errno 111] Connection refused')))
2025-05-23 04:40:11,060 - error_logger - ERROR - Error in telegram_update: urllib3 HTTPError HTTPSConnectionPool(host='api.telegram.org', port=443): Max retries exceeded with url: /bot7593677131:AAEpUpS8NkD6gIOU5o26xvtbjOq15g_rLis/getUpdates (Caused by ProxyError('Cannot connect to proxy.', NewConnectionError('<telegram.vendor.ptb_urllib3.urllib3.connection.VerifiedHTTPSConnection object at 0x729164505d50>: Failed to establish a new connection: [Errno 111] Connection refused')))
2025-05-23 05:10:09,384 - error_logger - ERROR - Error in telegram_update: urllib3 HTTPError HTTPSConnectionPool(host='api.telegram.org', port=443): Max retries exceeded with url: /bot7593677131:AAEpUpS8NkD6gIOU5o26xvtbjOq15g_rLis/getUpdates (Caused by ProxyError('Cannot connect to proxy.', NewConnectionError('<telegram.vendor.ptb_urllib3.urllib3.connection.VerifiedHTTPSConnection object at 0x72916452c7d0>: Failed to establish a new connection: [Errno 111] Connection refused')))
2025-05-23 06:20:09,487 - error_logger - ERROR - Error in telegram_update: urllib3 HTTPError HTTPSConnectionPool(host='api.telegram.org', port=443): Max retries exceeded with url: /bot7593677131:AAEpUpS8NkD6gIOU5o26xvtbjOq15g_rLis/getUpdates (Caused by ProxyError('Cannot connect to proxy.', NewConnectionError('<telegram.vendor.ptb_urllib3.urllib3.connection.VerifiedHTTPSConnection object at 0x72916452ea50>: Failed to establish a new connection: [Errno 111] Connection refused')))
2025-05-23 09:08:06,933 - error_logger - ERROR - Error in telegram_update: urllib3 HTTPError HTTPSConnectionPool(host='api.telegram.org', port=443): Max retries exceeded with url: /bot7593677131:AAEpUpS8NkD6gIOU5o26xvtbjOq15g_rLis/getUpdates (Caused by ProxyError('Cannot connect to proxy.', NewConnectionError('<telegram.vendor.ptb_urllib3.urllib3.connection.VerifiedHTTPSConnection object at 0x729164504850>: Failed to establish a new connection: [Errno 111] Connection refused')))
2025-05-23 13:06:06,348 - error_logger - ERROR - Error in telegram_update: urllib3 HTTPError HTTPSConnectionPool(host='api.telegram.org', port=443): Max retries exceeded with url: /bot7593677131:AAEpUpS8NkD6gIOU5o26xvtbjOq15g_rLis/getUpdates (Caused by ProxyError('Cannot connect to proxy.', NewConnectionError('<telegram.vendor.ptb_urllib3.urllib3.connection.VerifiedHTTPSConnection object at 0x729164507710>: Failed to establish a new connection: [Errno 111] Connection refused')))
2025-05-23 18:28:03,703 - error_logger - ERROR - Error in forward: 'NoneType' object has no attribute 'text'
2025-05-23 18:28:04,105 - error_logger - ERROR - Error in telegram_update: 'NoneType' object has no attribute 'text'
2025-05-24 01:48:06,887 - error_logger - ERROR - Error in telegram_update: urllib3 HTTPError HTTPSConnectionPool(host='api.telegram.org', port=443): Max retries exceeded with url: /bot7593677131:AAEpUpS8NkD6gIOU5o26xvtbjOq15g_rLis/getUpdates (Caused by ProxyError('Cannot connect to proxy.', NewConnectionError('<telegram.vendor.ptb_urllib3.urllib3.connection.VerifiedHTTPSConnection object at 0x7ed8944f7910>: Failed to establish a new connection: [Errno 111] Connection refused')))
2025-05-24 04:36:06,431 - error_logger - ERROR - Error in telegram_update: urllib3 HTTPError HTTPSConnectionPool(host='api.telegram.org', port=443): Max retries exceeded with url: /bot7593677131:AAEpUpS8NkD6gIOU5o26xvtbjOq15g_rLis/getUpdates (Caused by ProxyError('Cannot connect to proxy.', NewConnectionError('<telegram.vendor.ptb_urllib3.urllib3.connection.VerifiedHTTPSConnection object at 0x7ed8944f21d0>: Failed to establish a new connection: [Errno 111] Connection refused')))
